<?xml version='1.0'?>
<sdf version='1.3'>
  <model name='nao-v4'>
    <link name='base_link'>
      <pose>0 0 0.3331 0 -0 0</pose>
      <inertial>
        <pose>-0.00413 0.00009 0.04342 0 -0 0</pose>
        <mass>1.04956</mass>
        <!--<inertia>
          <ixx>0.00506234</ixx>
          <ixy>1.43116e-05</ixy>
          <ixz>0.000155191</ixz>
          <iyy>0.00488014</iyy>
          <iyz>-2.70793e-05</iyz>
          <izz>0.0016103</izz>
        </inertia>-->
	<inertia>
          <ixx>0.007041</ixx>
          <ixy>0.000014</ixy>
          <ixz>-0.000033</ixz>
          <iyy>0.006877</iyy>
          <iyz>-0.000023</iyz>
          <izz>0.001628</izz>
        </inertia>
      </inertial>
      <collision name='base_link_collision_torso'>
        <pose>0 0 0 -1.57 -0 0</pose>
        <geometry>
          <mesh>
            <scale>0.001 0.001 0.001</scale>
            <uri>model://nao-v4/meshes/V40/collision/Torso.dae</uri>
          </mesh>
        </geometry>
      </collision>
      <visual name='base_link_visual_torso'>
        <pose>0 0 0 -1.57 -0 0</pose>
        <geometry>
          <mesh>
            <scale>0.001 0.001 0.001</scale>
            <uri>model://nao-v4/meshes/V40/visual/Torso.dae</uri>
          </mesh>
        </geometry>
      </visual>
      <velocity_decay>
        <linear>0</linear>
        <angular>0</angular>
      </velocity_decay>
    </link>
    <link name='HeadYawLink'>
      <pose>0 0 0.4596 0 -0 0</pose>
      <inertial>
        <pose>-1e-05 0 -0.02742 0 -0 0</pose>
        <mass>0.06442</mass>
        <!--<inertia>
          <ixx>7.4993e-05</ixx>
          <ixy>1.57e-09</ixy>
          <ixz>-1.834e-08</ixz>
          <iyy>7.6e-05</iyy>
          <iyz>-5.295e-08</iyz>
          <izz>5.53373e-06</izz>
        </inertia>-->
	<inertia>
          <ixx>0.000123</ixx>
          <ixy>0.000000</ixy>
          <ixz>-0.000000</ixz>
          <iyy>0.000124</iyy>
          <iyz>-0.000000</iyz>
          <izz>0.000006</izz>
        </inertia>
      </inertial>
      <collision name='HeadYawLink_collision'>
        <pose>0 0 0 -1.57 -0 0</pose>
        <geometry>
          <mesh>
            <scale>0.001 0.001 0.001</scale>
            <uri>model://nao-v4/meshes/V40/collision/HeadYaw.dae</uri>
          </mesh>
        </geometry>
      </collision>
      <visual name='HeadYawLink_visual'>
        <pose>0 0 0 -1.57 -0 0</pose>
        <geometry>
          <mesh>
            <scale>0.001 0.001 0.001</scale>
            <uri>model://nao-v4/meshes/V40/visual/HeadYaw.dae</uri>
          </mesh>
        </geometry>
      </visual>
      <velocity_decay>
        <linear>0</linear>
        <angular>0</angular>
      </velocity_decay>
    </link>
    <joint name='HeadYaw' type='revolute'>
      <child>HeadYawLink</child>
      <parent>base_link</parent>
      <axis>
        <xyz>0 0 1</xyz>
        <limit>
          <lower>-2.0857</lower>
          <upper>2.0857</upper>
        </limit>
        <dynamics/>

      </axis>
    </joint>
    <link name='HeadPitchLink'>
      <pose>0 0 0.4596 0 -0 0</pose>
      <inertial>
        <pose>-0.00112 0 0.05258 0 -0 0</pose>
        <mass>0.60533</mass>
        <!--<inertia>
          <ixx>0.0026313</ixx>
          <ixy>8.78814e-06</ixy>
          <ixz>4.09847e-05</ixz>
          <iyy>0.00249112</iyy>
          <iyz>-2.99579e-05</iyz>
          <izz>0.000985736</izz>
        </inertia>-->
	<inertia>
          <ixx>0.004305</ixx>
          <ixy>0.000009</ixy>
          <ixz>0.000005</ixz>
          <iyy>0.004165</iyy>
          <iyz>-0.000029</iyz>
          <izz>0.000986</izz>
        </inertia>
      </inertial>
      <collision name='HeadPitchLink_collision'>
        <pose>0 0 0 -1.57 -0 0</pose>
        <geometry>
          <mesh>
            <scale>0.001 0.001 0.001</scale>
            <uri>model://nao-v4/meshes/V40/collision/HeadPitch.dae</uri>
          </mesh>
        </geometry>
      </collision>
      <visual name='HeadPitchLink_visual'>
        <pose>0 0 0 -1.57 -0 0</pose>
        <geometry>
          <mesh>
            <scale>0.001 0.001 0.001</scale>
            <uri>model://nao-v4/meshes/V40/visual/HeadPitch.dae</uri>
          </mesh>
        </geometry>
      </visual>
      <velocity_decay>
        <linear>0</linear>
        <angular>0</angular>
      </velocity_decay>
    </link>
    <joint name='HeadPitch' type='revolute'>
      <child>HeadPitchLink</child>
      <parent>HeadYawLink</parent>
      <axis>
        <xyz>0 1 0</xyz>
        <limit>
          <lower>-1e+16</lower>
          <upper>1e+16</upper>
        </limit>
        <dynamics/>

      </axis>
    </joint>
    <link name='LHipYawPitchLink'>
      <pose>0 0.05 0.2481 0 -0 0</pose>
      <inertial>
        <pose>-0.00781 -0.01114 0.02661 0 -0 0</pose>
        <mass>0.06981</mass>
        <!--<inertia>
          <ixx>8.15023e-05</ixx>
          <ixy>-4.99449e-06</ixy>
          <ixz>1.27482e-05</ixz>
          <iyy>0.000101326</iyy>
          <iyz>2.34547e-05</iyz>
          <izz>6.26236e-05</izz>
        </inertia>-->
	<inertia>
          <ixx>0.000140</ixx>
          <ixy>0.000001</ixy>
          <ixz>-0.000002</ixz>
          <iyy>0.000155</iyy>
          <iyz>0.000003</iyz>
          <izz>0.000076</izz>
        </inertia>
      </inertial>
      <collision name='LHipYawPitchLink_collision'>
        <pose>0 0 0 -1.57 -0 0</pose>
        <geometry>
          <mesh>
            <scale>0.001 0.001 0.001</scale>
            <uri>model://nao-v4/meshes/V40/collision/LHipYawPitch.dae</uri>
          </mesh>
        </geometry>
      </collision>
      <visual name='LHipYawPitchLink_visual'>
        <pose>0 0 0 -1.57 -0 0</pose>
        <geometry>
          <mesh>
            <scale>0.001 0.001 0.001</scale>
            <uri>model://nao-v4/meshes/V40/visual/LHipYawPitch.dae</uri>
          </mesh>
        </geometry>
      </visual>
      <velocity_decay>
        <linear>0</linear>
        <angular>0</angular>
      </velocity_decay>
    </link>
    <joint name='LHipYawPitch' type='revolute'>
      <child>LHipYawPitchLink</child>
      <parent>base_link</parent>
      <axis>
        <xyz>0 0.707107 -0.707107</xyz>
        <limit>
          <lower>-1e+16</lower>
          <upper>1e+16</upper>
        </limit>
        <dynamics/>

      </axis>
    </joint>
    <link name='LHipRollLink'>
      <pose>0 0.05 0.2481 0 -0 0</pose>
      <inertial>
        <pose>-0.01549 0.00029 -0.00515 0 -0 0</pose>
        <mass>0.13053</mass>
        <!--<inertia>
          <ixx>2.75835e-05</ixx>
          <ixy>-2.233e-08</ixy>
          <ixz>-4.08164e-06</ixz>
          <iyy>9.82706e-05</iyy>
          <iyz>-4.19e-09</iyz>
          <izz>8.80997e-05</izz>
        </inertia>-->
	<inertia>
          <ixx>0.000031</ixx>
          <ixy>-0.000001</ixy>
          <ixz>0.000006</ixz>
          <iyy>0.000133</iyy>
          <iyz>-0.000000</iyz>
          <izz>0.000119</izz>
        </inertia>
      </inertial>
      <collision name='LHipRollLink_collision'>
        <pose>0 0 0 -1.57 -0 0</pose>
        <geometry>
          <mesh>
            <scale>0.001 0.001 0.001</scale>
            <uri>model://nao-v4/meshes/V40/collision/LHipRoll.dae</uri>
          </mesh>
        </geometry>
      </collision>
      <visual name='LHipRollLink_visual'>
        <pose>0 0 0 -1.57 -0 0</pose>
        <geometry>
          <mesh>
            <scale>0.001 0.001 0.001</scale>
            <uri>model://nao-v4/meshes/V40/visual/LHipRoll.dae</uri>
          </mesh>
        </geometry>
      </visual>
      <velocity_decay>
        <linear>0</linear>
        <angular>0</angular>
      </velocity_decay>
    </link>
    <joint name='LHipRoll' type='revolute'>
      <child>LHipRollLink</child>
      <parent>LHipYawPitchLink</parent>
      <axis>
        <xyz>1 0 0</xyz>
        <limit>
          <lower>-1e+16</lower>
          <upper>1e+16</upper>
        </limit>
        <dynamics/>

      </axis>
    </joint>
    <link name='LHipPitchLink'>
      <pose>0 0.05 0.2481 0 -0 0</pose>
      <inertial>
        <pose>0.00138 0.00221 -0.05373 0 -0 0</pose>
        <mass>0.38968</mass>
        <!--<inertia>
          <ixx>0.00163672</ixx>
          <ixy>9.2451e-07</ixy>
          <ixz>8.53067e-05</ixz>
          <iyy>0.00159107</iyy>
          <iyz>3.83616e-05</iyz>
          <izz>0.000303743</izz>
        </inertia>-->
	<inertia>
          <ixx>0.002764</ixx>
          <ixy>0.000002</ixy>
          <ixz>0.000056</ixz>
          <iyy>0.002717</iyy>
          <iyz>-0.000008</iyz>
          <izz>0.000306</izz>
        </inertia>
      </inertial>
      <collision name='LHipPitchLink_collision'>
        <pose>0 0 0 -1.57 -0 0</pose>
        <geometry>
          <mesh>
            <scale>0.001 0.001 0.001</scale>
            <uri>model://nao-v4/meshes/V40/collision/LHipPitch.dae</uri>
          </mesh>
        </geometry>
      </collision>
      <visual name='LHipPitchLink_visual'>
        <pose>0 0 0 -1.57 -0 0</pose>
        <geometry>
          <mesh>
            <scale>0.001 0.001 0.001</scale>
            <uri>model://nao-v4/meshes/V40/visual/LHipPitch.dae</uri>
          </mesh>
        </geometry>
      </visual>
      <velocity_decay>
        <linear>0</linear>
        <angular>0</angular>
      </velocity_decay>
    </link>
    <joint name='LHipPitch' type='revolute'>
      <child>LHipPitchLink</child>
      <parent>LHipRollLink</parent>
      <axis>
        <xyz>0 1 0</xyz>
        <limit>
          <lower>-1e+16</lower>
          <upper>1e+16</upper>
        </limit>
        <dynamics/>

      </axis>
    </joint>
    <link name='LKneePitchLink'>
      <pose>0 0.05 0.1481 0 -0 0</pose>
      <inertial>
        <pose>0.00453 0.00225 -0.04936 0 -0 0</pose>
        <mass>0.29142</mass>
        <!--<inertia>
          <ixx>0.00118208</ixx>
          <ixy>6.3362e-07</ixy>
          <ixz>3.6497e-05</ixz>
          <iyy>0.00112865</iyy>
          <iyz>3.94952e-05</iyz>
          <izz>0.000193227</izz>
        </inertia>-->
	<inertia>
          <ixx>0.001894</ixx>
          <ixy>0.000004</ixy>
          <ixz>-0.000029</ixz>
          <iyy>0.001845</iyy>
          <iyz>0.000007</iyz>
          <izz>0.000201</izz>
        </inertia>
      </inertial>
      <collision name='LKneePitchLink_collision'>
        <pose>0 0 0 -1.57 -0 0</pose>
        <geometry>
          <mesh>
            <scale>0.001 0.001 0.001</scale>
            <uri>model://nao-v4/meshes/V40/collision/LKneePitch.dae</uri>
          </mesh>
        </geometry>
      </collision>
      <visual name='LKneePitchLink_visual'>
        <pose>0 0 0 -1.57 -0 0</pose>
        <geometry>
          <mesh>
            <scale>0.001 0.001 0.001</scale>
            <uri>model://nao-v4/meshes/V40/visual/LKneePitch.dae</uri>
          </mesh>
        </geometry>
      </visual>
      <velocity_decay>
        <linear>0</linear>
        <angular>0</angular>
      </velocity_decay>
    </link>
    <joint name='LKneePitch' type='revolute'>
      <child>LKneePitchLink</child>
      <parent>LHipPitchLink</parent>
      <axis>
        <xyz>0 1 0</xyz>
        <limit>
          <lower>-1e+16</lower>
          <upper>1e+16</upper>
        </limit>
        <dynamics/>

      </axis>
    </joint>
    <link name='LAnklePitchLink'>
      <pose>0 0.05 0.0452 0 -0 0</pose>
      <inertial>
        <pose>0.00045 0.00029 0.00685 0 -0 0</pose>
        <mass>0.13416</mass>
        <!--<inertia>
          <ixx>3.85098e-05</ixx>
          <ixy>-2.634e-08</ixy>
          <ixz>3.86194e-06</ixz>
          <iyy>7.42653e-05</iyy>
          <iyz>1.834e-08</iyz>
          <izz>5.48654e-05</izz>
        </inertia>-->
	<inertia>
          <ixx>0.000045</ixx>
          <ixy>-0.000000</ixy>
          <ixz>0.000004</ixz>
          <iyy>0.000081</iyy>
          <iyz>0.000000</iyz>
          <izz>0.000055</izz>
        </inertia>
      </inertial>
      <collision name='LAnklePitchLink_collision'>
        <pose>0 0 0 -1.57 -0 0</pose>
        <geometry>
          <mesh>
            <scale>0.001 0.001 0.001</scale>
            <uri>model://nao-v4/meshes/V40/collision/LAnklePitch.dae</uri>
          </mesh>
        </geometry>
      </collision>
      <visual name='LAnklePitchLink_visual'>
        <pose>0 0 0 -1.57 -0 0</pose>
        <geometry>
          <mesh>
            <scale>0.001 0.001 0.001</scale>
            <uri>model://nao-v4/meshes/V40/visual/LAnklePitch.dae</uri>
          </mesh>
        </geometry>
      </visual>
      <velocity_decay>
        <linear>0</linear>
        <angular>0</angular>
      </velocity_decay>
    </link>
    <joint name='LAnklePitch' type='revolute'>
      <child>LAnklePitchLink</child>
      <parent>LKneePitchLink</parent>
      <axis>
        <xyz>0 1 0</xyz>
        <limit>
          <lower>-1e+16</lower>
          <upper>1e+16</upper>
        </limit>
        <dynamics/>

      </axis>
    </joint>
    <link name='LAnkleRollLink'>
      <pose>0 0.05 0.0452 0 -0 0</pose>
      <inertial>
        <pose>0.02542 0.0033 -0.03239 0 -0 0</pose>
        <mass>0.16184</mass>
        <!--<inertia>
          <ixx>0.000269442</ixx>
          <ixy>-5.69572e-06</ixy>
          <ixz>0.000139379</ixz>
          <iyy>0.000644343</iyy>
          <iyz>1.87409e-05</iyz>
          <izz>0.000525757</izz>
        </inertia>-->
 	<inertia>
          <ixx>0.000441</ixx>
          <ixy>0.000008</ixy>
          <ixz>0.000006</ixz>
          <iyy>0.000919</iyy>
          <iyz>0.000001</iyz>
          <izz>0.000632</izz>
        </inertia>
      </inertial>
      <collision name='LAnkleRollLink_collision'>
        <pose>0 0 0 -1.57 -0 0</pose>
        <geometry>
          <mesh>
            <scale>0.001 0.001 0.001</scale>
            <uri>model://nao-v4/meshes/V40/visual/LAnkleRoll.dae</uri>
          </mesh>
        </geometry>
      </collision>
      <visual name='LAnkleRollLink_visual'>
        <pose>0 0 0 -1.57 -0 0</pose>
        <geometry>
          <mesh>
            <scale>0.001 0.001 0.001</scale>
            <uri>model://nao-v4/meshes/V40/visual/LAnkleRoll.dae</uri>
          </mesh>
        </geometry>
      </visual>
      <velocity_decay>
        <linear>0</linear>
        <angular>0</angular>
      </velocity_decay>
    </link>
    <joint name='LAnkleRoll' type='revolute'>
      <child>LAnkleRollLink</child>
      <parent>LAnklePitchLink</parent>
      <axis>
        <xyz>1 0 0</xyz>
        <limit>
          <lower>-1e+16</lower>
          <upper>1e+16</upper>
        </limit>
        <dynamics/>

      </axis>
    </joint>
    <link name='LShoulderPitchLink'>
      <pose>0 0.098 0.4331 0 -0 0</pose>
      <inertial>
        <pose>-0.00165 -0.02663 0.00014 0 -0 0</pose>
        <mass>0.07504</mass>
        <!--<inertia>
          <ixx>8.42843e-05</ixx>
          <ixy>-2.02802e-06</ixy>
          <ixz>2.338e-08</ixz>
          <iyy>1.41556e-05</iyy>
          <iyz>-1.972e-08</iyz>
          <izz>8.64195e-05</izz>
        </inertia>-->
	<inertia>
          <ixx>0.000138</ixx>
          <ixy>0.000005</ixy>
          <ixz>0.000000</ixz>
          <iyy>0.000014</iyy>
          <iyz>-0.000000</iyz>
          <izz>0.000140</izz>
        </inertia>
      </inertial>
      <collision name='LShoulderPitchLink_collision'>
        <pose>0 0 0 -1.57 -0 0</pose>
        <geometry>
          <mesh>
            <scale>0.001 0.001 0.001</scale>
            <uri>model://nao-v4/meshes/V40/collision/LShoulderPitch.dae</uri>
          </mesh>
        </geometry>
      </collision>
      <visual name='LShoulderPitchLink_visual'>
        <pose>0 0 0 -1.57 -0 0</pose>
        <geometry>
          <mesh>
            <scale>0.001 0.001 0.001</scale>
            <uri>model://nao-v4/meshes/V40/visual/LShoulderPitch.dae</uri>
          </mesh>
        </geometry>
      </visual>
      <velocity_decay>
        <linear>0</linear>
        <angular>0</angular>
      </velocity_decay>
    </link>
    <joint name='LShoulderPitch' type='revolute'>
      <child>LShoulderPitchLink</child>
      <parent>base_link</parent>
      <axis>
        <xyz>0 1 0</xyz>
        <limit>
          <lower>-1e+16</lower>
          <upper>1e+16</upper>
        </limit>
        <dynamics/>

      </axis>
    </joint>
    <link name='LShoulderRollLink'>
      <pose>0 0.098 0.4331 0 -0 0</pose>
      <inertial>
        <pose>0.02455 0.00563 0.0033 0 -0 0</pose>
        <mass>0.15777</mass>
        <!--<inertia>
          <ixx>9.38999e-05</ixx>
          <ixy>-4.71445e-05</ixy>
          <ixz>-2.69947e-05</ixz>
          <iyy>0.000371519</iyy>
          <iyz>-2.45977e-06</iyz>
          <izz>0.000341901</izz>
        </inertia>-->
	<inertia>
          <ixx>0.000101</ixx>
          <ixy>-0.000025</ixy>
          <ixz>-0.000014</ixz>
          <iyy>0.000468</iyy>
          <iyz>0.000000</iyz>
          <izz>0.000442</izz>
        </inertia>
      </inertial>
      <collision name='LShoulderRollLink_collision'>
        <pose>0 0 0 -1.57 -0 0</pose>
        <geometry>
          <mesh>
            <scale>0.001 0.001 0.001</scale>
            <uri>model://nao-v4/meshes/V40/collision/LShoulderRoll.dae</uri>
          </mesh>
        </geometry>
      </collision>
      <visual name='LShoulderRollLink_visual'>
        <pose>0 0 0 -1.57 -0 0</pose>
        <geometry>
          <mesh>
            <scale>0.001 0.001 0.001</scale>
            <uri>model://nao-v4/meshes/V40/visual/LShoulderRoll.dae</uri>
          </mesh>
        </geometry>
      </visual>
      <velocity_decay>
        <linear>0</linear>
        <angular>0</angular>
      </velocity_decay>
    </link>
    <joint name='LShoulderRoll' type='revolute'>
      <child>LShoulderRollLink</child>
      <parent>LShoulderPitchLink</parent>
      <axis>
        <xyz>0 0 1</xyz>
        <limit>
          <lower>-1e+16</lower>
          <upper>1e+16</upper>
        </limit>
        <dynamics/>

      </axis>
    </joint>
    <link name='LElbowYawLink'>
      <pose>0.105 0.113 0.4331 0 -0 0</pose>
      <inertial>
        <pose>-0.02744 0 -0.00014 0 -0 0</pose>
        <mass>0.06483</mass>
        <!--<inertia>
          <ixx>5.59715e-06</ixx>
          <ixy>4.21e-09</ixy>
          <ixz>4.319e-08</ixz>
          <iyy>7.54331e-05</iyy>
          <iyz>-1.84e-09</iyz>
          <izz>7.64434e-05</izz>
        </inertia>-->
	<inertia>
          <ixx>0.000006</ixx>
          <ixy>0.000000</ixy>
          <ixz>0.000000</ixz>
          <iyy>0.000124</iyy>
          <iyz>-0.000000</iyz>
          <izz>0.000125</izz>
        </inertia>
      </inertial>
      <velocity_decay>
        <linear>0</linear>
        <angular>0</angular>
      </velocity_decay>
    </link>
    <joint name='LElbowYaw' type='revolute'>
      <child>LElbowYawLink</child>
      <parent>LShoulderRollLink</parent>
      <axis>
        <xyz>1 0 0</xyz>
        <limit>
          <lower>-1e+16</lower>
          <upper>1e+16</upper>
        </limit>
        <dynamics/>

      </axis>
    </joint>
    <link name='LElbowRollLink'>
      <pose>0.105 0.113 0.4331 0 -0 0</pose>
      <inertial>
        <pose>0.02556 0.00281 0.00076 0 -0 0</pose>
        <mass>0.07761</mass>
        <!--<inertia>
          <ixx>2.53322e-05</ixx>
          <ixy>-2.34271e-06</ixy>
          <ixz>7.459e-08</ixz>
          <iyy>8.91322e-05</iyy>
          <iyz>-2.655e-08</iyz>
          <izz>8.72873e-05</izz>
        </inertia>-->
	<inertia>
          <ixx>0.000026</ixx>
          <ixy>0.000003</ixy>
          <ixz>0.000002</ixz>
          <iyy>0.000140</iyy>
          <iyz>0.000000</iyz>
          <izz>0.000139</izz>
        </inertia>
      </inertial>
      <collision name='LElbowRollLink_collision'>
        <pose>0 0 0 -1.57 -0 0</pose>
        <geometry>
          <mesh>
            <scale>0.001 0.001 0.001</scale>
            <uri>model://nao-v4/meshes/V40/collision/LElbowRollComplete.dae</uri>
          </mesh>
        </geometry>
      </collision>
      <visual name='LElbowRollLink_visual'>
        <pose>0 0 0 -1.57 -0 0</pose>
        <geometry>
          <mesh>
            <scale>0.001 0.001 0.001</scale>
            <uri>model://nao-v4/meshes/V40/visual/LElbowRollComplete.dae</uri>
          </mesh>
        </geometry>
      </visual>
      <velocity_decay>
        <linear>0</linear>
        <angular>0</angular>
      </velocity_decay>
    </link>
    <joint name='LElbowRoll' type='revolute'>
      <child>LElbowRollLink</child>
      <parent>LElbowYawLink</parent>
      <axis>
        <xyz>0 0 1</xyz>
        <limit>
          <lower>-1e+16</lower>
          <upper>1e+16</upper>
        </limit>
        <dynamics/>

      </axis>
    </joint>
    <!--<link name='LWristYawLink'>
      <pose>0.16095 0.113 0.4331 0 -0 0</pose>
      <inertial>
        <pose>0.03434 -0.00088 0.00308 0 -0 0</pose>
        <mass>0.18533</mass>
        <inertia>
          <ixx>7.05493e-05</ixx>
          <ixy>5.71599e-06</ixy>
          <ixz>-2.24744e-05</ixz>
          <iyy>0.000356062</iyy>
          <iyz>3.17771e-06</iyz>
          <izz>0.000351919</izz>
        </inertia>
      </inertial>
      <collision name='LWristYawLink_collision'>
        <pose>0 0 0 0 -0 0</pose>
        <geometry>
          <mesh>
            <scale>0.001 0.001 0.001</scale>
            <uri>model://nao-v4/meshes/V40/collision/WristYaw.dae</uri>
          </mesh>
        </geometry>
      </collision>
      <visual name='LWristYawLink_visual'>
        <pose>0 0 0 -1.57 -0 0</pose>
        <geometry>
          <mesh>
            <scale>0.001 0.001 0.001</scale>
            <uri>model://nao-v4/meshes/V40/visual/WristYaw.dae</uri>
          </mesh>
        </geometry>
      </visual>
      <velocity_decay>
        <linear>0</linear>
        <angular>0</angular>
      </velocity_decay>
    </link>
    <joint name='LWristYaw' type='revolute'>
      <child>LWristYawLink</child>
      <parent>LElbowRollLink</parent>
      <axis>
        <xyz>1 0 0</xyz>
        <limit>
          <lower>-1e+16</lower>
          <upper>1e+16</upper>
        </limit>
        <dynamics/>

      </axis>
    </joint>-->
    <link name='RHipYawPitchLink'>
      <pose>0 -0.05 0.2481 0 -0 0</pose>
      <inertial>
        <pose>-0.00781 0.01114 0.02661 0 -0 0</pose>
        <mass>0.06981</mass>
        <!--<inertia>
          <ixx>8.9972e-05</ixx>
          <ixy>5.00219e-06</ixy>
          <ixz>1.27352e-05</ixz>
          <iyy>0.000105526</iyy>
          <iyz>-2.77008e-05</iyz>
          <izz>6.68872e-05</izz>
        </inertia>-->
	<inertia>
          <ixx>0.000153</ixx>
          <ixy>-0.000002</ixy>
          <ixz>-0.000002</ixz>
          <iyy>0.000162</iyy>
          <iyz>-0.000005</iyz>
          <izz>0.000081</izz>
        </inertia>
      </inertial>
      <collision name='RHipYawPitchLink_collision'>
        <pose>0 0 0 -1.57 -0 0</pose>
        <geometry>
          <mesh>
            <scale>0.001 0.001 0.001</scale>
            <uri>model://nao-v4/meshes/V40/collision/RHipYawPitch.dae</uri>
          </mesh>
        </geometry>
      </collision>
      <visual name='RHipYawPitchLink_visual'>
        <pose>0 0 0 -1.57 -0 0</pose>
        <geometry>
          <mesh>
            <scale>0.001 0.001 0.001</scale>
            <uri>model://nao-v4/meshes/V40/visual/RHipYawPitch.dae</uri>
          </mesh>
        </geometry>
      </visual>
      <velocity_decay>
        <linear>0</linear>
        <angular>0</angular>
      </velocity_decay>
    </link>
    <joint name='RHipYawPitch' type='revolute'>
      <child>RHipYawPitchLink</child>
      <parent>base_link</parent>
      <axis>
        <xyz>0 0.707107 0.707107</xyz>
        <limit>
          <lower>-1e+16</lower>
          <upper>1e+16</upper>
        </limit>
        <dynamics/>

      </axis>
    </joint>
    <link name='RHipRollLink'>
      <pose>0 -0.05 0.2481 0 -0 0</pose>
      <inertial>
        <pose>-0.01549 -0.00029 -0.00515 0 -0 0</pose>
        <mass>0.13053</mass>
        <!--<inertia>
          <ixx>2.75865e-05</ixx>
          <ixy>-1.919e-08</ixy>
          <ixz>-4.10822e-06</ixz>
          <iyy>9.827e-05</iyy>
          <iyz>2.51e-09</iyz>
          <izz>8.81033e-05</izz>
        </inertia>-->
	<inertia>
          <ixx>0.000031</ixx>
          <ixy>0.000001</ixy>
          <ixz>0.000006</ixz>
          <iyy>0.000133</iyy>
          <iyz>0.000000</iyz>
          <izz>0.000119</izz>
        </inertia>
      </inertial>
      <collision name='RHipRollLink_collision'>
        <pose>0 0 0 -1.57 -0 0</pose>
        <geometry>
          <mesh>
            <scale>0.001 0.001 0.001</scale>
            <uri>model://nao-v4/meshes/V40/collision/RHipRoll.dae</uri>
          </mesh>
        </geometry>
      </collision>
      <visual name='RHipRollLink_visual'>
        <pose>0 0 0 -1.57 -0 0</pose>
        <geometry>
          <mesh>
            <scale>0.001 0.001 0.001</scale>
            <uri>model://nao-v4/meshes/V40/visual/RHipRoll.dae</uri>
          </mesh>
        </geometry>
      </visual>
      <velocity_decay>
        <linear>0</linear>
        <angular>0</angular>
      </velocity_decay>
    </link>
    <joint name='RHipRoll' type='revolute'>
      <child>RHipRollLink</child>
      <parent>RHipYawPitchLink</parent>
      <axis>
        <xyz>1 0 0</xyz>
        <limit>
          <lower>-1e+16</lower>
          <upper>1e+16</upper>
        </limit>
        <dynamics/>

      </axis>
    </joint>
    <link name='RHipPitchLink'>
      <pose>0 -0.05 0.2481 0 -0 0</pose>
      <inertial>
        <pose>0.00138 -0.00221 -0.05373 0 -0 0</pose>
        <mass>0.38968</mass>
        <!--<inertia>
          <ixx>0.00163748</ixx>
          <ixy>-8.3954e-07</ixy>
          <ixz>8.5883e-05</ixz>
          <iyy>0.00159221</iyy>
          <iyz>-3.91763e-05</iyz>
          <izz>0.000303978</izz>
        </inertia>-->
	<inertia>
          <ixx>0.002765</ixx>
          <ixy>-0.000002</ixy>
          <ixz>0.000057</ixz>
          <iyy>0.002719</iyy>
          <iyz>0.000008</iyz>
          <izz>0.000307</izz>
        </inertia>
      </inertial>
      <collision name='RHipPitchLink_collision'>
        <pose>0 0 0 -1.57 -0 0</pose>
        <geometry>
          <mesh>
            <scale>0.001 0.001 0.001</scale>
            <uri>model://nao-v4/meshes/V40/collision/RHipPitch.dae</uri>
          </mesh>
        </geometry>
      </collision>
      <visual name='RHipPitchLink_visual'>
        <pose>0 0 0 -1.57 -0 0</pose>
        <geometry>
          <mesh>
            <scale>0.001 0.001 0.001</scale>
            <uri>model://nao-v4/meshes/V40/visual/RHipPitch.dae</uri>
          </mesh>
        </geometry>
      </visual>
      <velocity_decay>
        <linear>0</linear>
        <angular>0</angular>
      </velocity_decay>
    </link>
    <joint name='RHipPitch' type='revolute'>
      <child>RHipPitchLink</child>
      <parent>RHipRollLink</parent>
      <axis>
        <xyz>0 1 0</xyz>
        <limit>
          <lower>-1e+16</lower>
          <upper>1e+16</upper>
        </limit>
        <dynamics/>

      </axis>
    </joint>
    <link name='RKneePitchLink'>
      <pose>0 -0.05 0.1481 0 -0 0</pose>
      <inertial>
        <pose>0.00453 -0.00225 -0.04936 0 -0 0</pose>
        <mass>0.29142</mass>
        <!--<inertia>
          <ixx>0.00118283</ixx>
          <ixy>-8.965e-07</ixy>
          <ixz>2.79969e-05</ixz>
          <iyy>0.00112828</iyy>
          <iyz>-3.8476e-05</iyz>
          <izz>0.000191453</izz>
        </inertia>-->
	<inertia>
          <ixx>0.001895</ixx>
          <ixy>-0.000003</ixy>
          <ixz>-0.000029</ixz>
          <iyy>0.001844</iyy>
          <iyz>-0.000007</iyz>
          <izz>0.000197</izz>
        </inertia>
      </inertial>
      <collision name='RKneePitchLink_collision'>
        <pose>0 0 0 -1.57 -0 0</pose>
        <geometry>
          <mesh>
            <scale>0.001 0.001 0.001</scale>
            <uri>model://nao-v4/meshes/V40/collision/RKneePitch.dae</uri>
          </mesh>
        </geometry>
      </collision>
      <visual name='RKneePitchLink_visual'>
        <pose>0 0 0 -1.57 -0 0</pose>
        <geometry>
          <mesh>
            <scale>0.001 0.001 0.001</scale>
            <uri>model://nao-v4/meshes/V40/visual/RKneePitch.dae</uri>
          </mesh>
        </geometry>
      </visual>
      <velocity_decay>
        <linear>0</linear>
        <angular>0</angular>
      </velocity_decay>
    </link>
    <joint name='RKneePitch' type='revolute'>
      <child>RKneePitchLink</child>
      <parent>RHipPitchLink</parent>
      <axis>
        <xyz>0 1 0</xyz>
        <limit>
          <lower>-1e+16</lower>
          <upper>1e+16</upper>
        </limit>
        <dynamics/>

      </axis>
    </joint>
    <link name='RAnklePitchLink'>
      <pose>0 -0.05 0.0452 0 -0 0</pose>
      <inertial>
        <pose>0.00045 -0.00029 0.00685 0 -0 0</pose>
        <mass>0.13416</mass>
        <!--<inertia>
          <ixx>3.85081e-05</ixx>
          <ixy>6.434e-08</ixy>
          <ixz>3.87466e-06</ixz>
          <iyy>7.43108e-05</iyy>
          <iyz>-4.58e-09</iyz>
          <izz>5.49131e-05</izz>
        </inertia>-->
	<inertia>
          <ixx>0.000045</ixx>
          <ixy>0.000000</ixy>
          <ixz>0.000004</ixz>
          <iyy>0.000081</iyy>
          <iyz>-0.000000</iyz>
          <izz>0.000055</izz>
        </inertia>
      </inertial>
      <collision name='RAnklePitchLink_collision'>
        <pose>0 0 0 -1.57 -0 0</pose>
        <geometry>
          <mesh>
            <scale>0.001 0.001 0.001</scale>
            <uri>model://nao-v4/meshes/V40/collision/RAnklePitch.dae</uri>
          </mesh>
        </geometry>
      </collision>
      <visual name='RAnklePitchLink_visual'>
        <pose>0 0 0 -1.57 -0 0</pose>
        <geometry>
          <mesh>
            <scale>0.001 0.001 0.001</scale>
            <uri>model://nao-v4/meshes/V40/visual/RAnklePitch.dae</uri>
          </mesh>
        </geometry>
      </visual>
      <velocity_decay>
        <linear>0</linear>
        <angular>0</angular>
      </velocity_decay>
    </link>
    <joint name='RAnklePitch' type='revolute'>
      <child>RAnklePitchLink</child>
      <parent>RKneePitchLink</parent>
      <axis>
        <xyz>0 1 0</xyz>
        <limit>
          <lower>-1e+16</lower>
          <upper>1e+16</upper>
        </limit>
        <dynamics/>

      </axis>
    </joint>
    <link name='RAnkleRollLink'>
      <pose>0 -0.05 0.0452 0 -0 0</pose>
      <inertial>
        <pose>0.02542 -0.0033 -0.03239 0 -0 0</pose>
        <mass>0.16184</mass>
        <!--<inertia>
          <ixx>0.000269302</ixx>
          <ixy>5.87505e-06</ixy>
          <ixz>0.000139133</ixz>
          <iyy>0.000643474</iyy>
          <iyz>-1.88492e-05</iyz>
          <izz>0.000525035</izz>
        </inertia>-->
	<inertia>
          <ixx>0.000441</ixx>
          <ixy>-0.000008</ixy>
          <ixz>0.000006</ixz>
          <iyy>0.000917</iyy>
          <iyz>-0.000001</iyz>
          <izz>0.000631</izz>
        </inertia>
      </inertial>
      <collision name='RAnkleRollLink_collision'>
        <pose>0 0 0 -1.57 -0 0</pose>
        <geometry>
          <mesh>
            <scale>0.001 0.001 0.001</scale>
            <uri>model://nao-v4/meshes/V40/visual/RAnkleRoll.dae</uri>
          </mesh>
        </geometry>
      </collision>
      <visual name='RAnkleRollLink_visual'>
        <pose>0 0 0 -1.57 -0 0</pose>
        <geometry>
          <mesh>
            <scale>0.001 0.001 0.001</scale>
            <uri>model://nao-v4/meshes/V40/visual/RAnkleRoll.dae</uri>
          </mesh>
        </geometry>
      </visual>
      <velocity_decay>
        <linear>0</linear>
        <angular>0</angular>
      </velocity_decay>
    </link>
    <joint name='RAnkleRoll' type='revolute'>
      <child>RAnkleRollLink</child>
      <parent>RAnklePitchLink</parent>
      <axis>
        <xyz>1 0 0</xyz>
        <limit>
          <lower>-1e+16</lower>
          <upper>1e+16</upper>
        </limit>
        <dynamics/>

      </axis>
    </joint>
    <link name='RShoulderPitchLink'>
      <pose>0 -0.098 0.4331 0 -0 0</pose>
      <inertial>
        <pose>-0.00165 0.02663 0.00014 0 -0 0</pose>
        <mass>0.07504</mass>
        <!--<inertia>
          <ixx>8.42843e-05</ixx>
          <ixy>2.02802e-06</ixy>
          <ixz>2.338e-08</ixz>
          <iyy>1.41556e-05</iyy>
          <iyz>1.972e-08</iyz>
          <izz>8.64195e-05</izz>
        </inertia>-->
 	<inertia>
          <ixx>0.000138</ixx>
          <ixy>-0.000001</ixy>
          <ixz>0.000000</ixz>
          <iyy>0.000014</iyy>
          <iyz>0.000000</iyz>
          <izz>0.000140</izz>
        </inertia>
      </inertial>
      <collision name='RShoulderPitchLink_collision'>
        <pose>0 0 0 -1.57 -0 0</pose>
        <geometry>
          <mesh>
            <scale>0.001 0.001 0.001</scale>
            <uri>model://nao-v4/meshes/V40/collision/RShoulderPitch.dae</uri>
          </mesh>
        </geometry>
      </collision>
      <visual name='RShoulderPitchLink_visual'>
        <pose>0 0 0 -1.57 -0 0</pose>
        <geometry>
          <mesh>
            <scale>0.001 0.001 0.001</scale>
            <uri>model://nao-v4/meshes/V40/visual/RShoulderPitch.dae</uri>
          </mesh>
        </geometry>
      </visual>
      <velocity_decay>
        <linear>0</linear>
        <angular>0</angular>
      </velocity_decay>
    </link>
    <joint name='RShoulderPitch' type='revolute'>
      <child>RShoulderPitchLink</child>
      <parent>base_link</parent>
      <axis>
        <xyz>0 1 0</xyz>
        <limit>
          <lower>-1e+16</lower>
          <upper>1e+16</upper>
        </limit>
        <dynamics/>

      </axis>
    </joint>
    <link name='RShoulderRollLink'>
      <pose>0 -0.098 0.4331 0 -0 0</pose>
      <inertial>
        <pose>0.02455 -0.00563 0.0033 0 -0 0</pose>
        <mass>0.15777</mass>
        <!--<inertia>
          <ixx>0.00011012</ixx>
          <ixy>7.66913e-05</ixy>
          <ixz>-2.60461e-05</ixz>
          <iyy>0.000367577</iyy>
          <iyz>1.20983e-05</iyz>
          <izz>0.000354618</izz>
        </inertia>-->
	<inertia>
          <ixx>0.000126</ixx>
          <ixy>0.000040</ixy>
          <ixz>-0.000014</ixz>
          <iyy>0.000462</iyy>
          <iyz>0.000007</iyz>
          <izz>0.000462</izz>
        </inertia>
      </inertial>
      <collision name='RShoulderRollLink_collision'>
        <pose>0 0 0 -1.57 -0 0</pose>
        <geometry>
          <mesh>
            <scale>0.001 0.001 0.001</scale>
            <uri>model://nao-v4/meshes/V40/collision/RShoulderRoll.dae</uri>
          </mesh>
        </geometry>
      </collision>
      <visual name='RShoulderRollLink_visual'>
        <pose>0 0 0 -1.57 -0 0</pose>
        <geometry>
          <mesh>
            <scale>0.001 0.001 0.001</scale>
            <uri>model://nao-v4/meshes/V40/visual/RShoulderRoll.dae</uri>
          </mesh>
        </geometry>
      </visual>
      <velocity_decay>
        <linear>0</linear>
        <angular>0</angular>
      </velocity_decay>
    </link>
    <joint name='RShoulderRoll' type='revolute'>
      <child>RShoulderRollLink</child>
      <parent>RShoulderPitchLink</parent>
      <axis>
        <xyz>0 0 1</xyz>
        <limit>
          <lower>-1e+16</lower>
          <upper>1e+16</upper>
        </limit>
        <dynamics/>

      </axis>
    </joint>
    <link name='RElbowYawLink'>
      <pose>0.105 -0.113 0.4331 0 -0 0</pose>
      <inertial>
        <pose>-0.02744 0 -0.00014 0 -0 0</pose>
        <mass>0.06483</mass>
        <!--<inertia>
          <ixx>5.59715e-06</ixx>
          <ixy>4.21e-09</ixy>
          <ixz>4.319e-08</ixz>
          <iyy>7.54331e-05</iyy>
          <iyz>-1.84e-09</iyz>
          <izz>7.64434e-05</izz>
        </inertia>-->
	<inertia>
          <ixx>0.000006</ixx>
          <ixy>0.000000</ixy>
          <ixz>0.000000</ixz>
          <iyy>0.000124</iyy>
          <iyz>-0.000000</iyz>
          <izz>0.000125</izz>
        </inertia>
      </inertial>
      <velocity_decay>
        <linear>0</linear>
        <angular>0</angular>
      </velocity_decay>
    </link>
    <joint name='RElbowYaw' type='revolute'>
      <child>RElbowYawLink</child>
      <parent>RShoulderRollLink</parent>
      <axis>
        <xyz>1 0 0</xyz>
        <limit>
          <lower>-1e+16</lower>
          <upper>1e+16</upper>
        </limit>
        <dynamics/>

      </axis>
    </joint>
    <link name='RElbowRollLink'>
      <pose>0.105 -0.113 0.4331 0 -0 0</pose>
      <inertial>
        <pose>0.02556 -0.00281 0.00076 0 -0 0</pose>
        <mass>0.07761</mass>
        <!--<inertia>
          <ixx>2.53907e-05</ixx>
          <ixy>2.33243e-06</ixy>
          <ixz>-6.0117e-07</ixz>
          <iyy>8.92204e-05</iyy>
          <iyz>2.694e-08</iyz>
          <izz>8.72484e-05</izz>
        </inertia>-->
	<inertia>
          <ixx>0.000026</ixx>
          <ixy>-0.000003</ixy>
          <ixz>0.000001</ixz>
          <iyy>0.000140</iyy>
          <iyz>-0.000000</iyz>
          <izz>0.000139</izz>
        </inertia>
      </inertial>
      <collision name='RElbowRollLink_collision'>
        <pose>0 0 0 -1.57 -0 0</pose>
        <geometry>
          <mesh>
            <scale>0.001 0.001 0.001</scale>
            <uri>model://nao-v4/meshes/V40/collision/RElbowRollComplete.dae</uri>
          </mesh>
        </geometry>
      </collision>
      <visual name='RElbowRollLink_visual'>
        <pose>0 0 0 -1.57 -0 0</pose>
        <geometry>
          <mesh>
            <scale>0.001 0.001 0.001</scale>
            <uri>model://nao-v4/meshes/V40/visual/RElbowRollComplete.dae</uri>
          </mesh>
        </geometry>
      </visual>
      <velocity_decay>
        <linear>0</linear>
        <angular>0</angular>
      </velocity_decay>
    </link>
    <joint name='RElbowRoll' type='revolute'>
      <child>RElbowRollLink</child>
      <parent>RElbowYawLink</parent>
      <axis>
        <xyz>0 0 1</xyz>
        <limit>
          <lower>-1e+16</lower>
          <upper>1e+16</upper>
        </limit>
        <dynamics/>

      </axis>
    </joint>
    <!--<link name='RWristYawLink'>
      <pose>0.16095 -0.113 0.4331 0 -0 0</pose>
      <inertial>
        <pose>0.03434 0.00088 0.00308 0 -0 0</pose>
        <mass>0.18533</mass>
        <inertia>
          <ixx>7.05493e-05</ixx>
          <ixy>5.71599e-06</ixy>
          <ixz>-2.24744e-05</ixz>
          <iyy>0.000356062</iyy>
          <iyz>3.17771e-06</iyz>
          <izz>0.000351919</izz>
        </inertia>
      </inertial>
      <collision name='RWristYawLink_collision'>
        <pose>0 0 0 0 -0 0</pose>
        <geometry>
          <mesh>
            <scale>0.001 0.001 0.001</scale>
            <uri>model://nao-v4/meshes/V40/collision/WristYaw.dae</uri>
          </mesh>
        </geometry>
      </collision>
      <visual name='RWristYawLink_visual'>
        <pose>0 0 0 -1.57 -0 0</pose>
        <geometry>
          <mesh>
            <scale>0.001 0.001 0.001</scale>
            <uri>model://nao-v4/meshes/V40/visual/WristYaw.dae</uri>
          </mesh>
        </geometry>
      </visual>
      <velocity_decay>
        <linear>0</linear>
        <angular>0</angular>
      </velocity_decay>
    </link>
    <joint name='RWristYaw' type='revolute'>
      <child>RWristYawLink</child>
      <parent>RElbowRollLink</parent>
      <axis>
        <xyz>1 0 0</xyz>
        <limit>
          <lower>-1e+16</lower>
          <upper>1e+16</upper>
        </limit>
        <dynamics/>

      </axis>
    </joint>-->

    <link name="camera_head_top">
      <pose>0.017 -0.0008 0.533 1.57 -0.0209 -3.14</pose>
      <inertial>
        <mass>0.05</mass>
      </inertial>  
      <sensor name='cam_sensor_top' type='camera'>
        <pose>0 0 0 1.57 0 3.14</pose>
        <update_rate>20</update_rate>
        <camera>
          <horizontal_fov>1.57</horizontal_fov>
          <image>
            <width>640</width>
            <height>480</height>
            <format>R8G8B8</format>
          </image>
          <clip>
	    <near>0.5</near>
	    <far>5</far>
          </clip>
        </camera>
        <plugin name='camera_dump' filename='libcamera_nao.so'/>
      </sensor>     
      <visual name="visual">
        <geometry>
          <mesh>
            <uri>model://pioneer2dxJde/meshes/sonyvid30/sonyvid30_top.dae</uri>
            <scale>1.5 1.5 1.5</scale>
          </mesh>
        </geometry>
      </visual>  
      <collision name="collision">
        <geometry>
          <box>
            <size>0.01 0.01 0.01</size>
          </box>
        </geometry>
        <surface>
          <friction>
            <ode>
              <mu>100000.0</mu>
              <mu2>100000.0</mu2>
              <slip1>0.0</slip1>
              <slip2>0.0</slip2>
            </ode>
          </friction>
        </surface>
      </collision>
    </link>
    <joint type="revolute" name="camera_top">
      <pose>0 0 0.0734 0 0 0</pose>
      <child>HeadPitchLink</child>
      <parent>camera_head_top</parent>
      <axis>
        <limit>
          <lower>0</lower>
          <upper>0</upper>
        </limit>
        <xyz>0 0 0</xyz>
      </axis>
    </joint>
    <link name="camera_head_bottom">
      <pose>0.019 -0.0008 0.502 1.57 -0.6929 -3.14</pose>
      <inertial>
        <mass>0.05</mass>
      </inertial>
      <sensor name='cam_sensor_bottom' type='camera'>
        <pose>0 0 0 1.57 0 3.14</pose>
        <update_rate>20</update_rate>
        <camera>
          <horizontal_fov>1.57</horizontal_fov>
          <image>
            <width>640</width>
            <height>480</height>
            <format>R8G8B8</format>
          </image>
          <clip>
	    <near>0.5</near>
	    <far>5</far>
          </clip>
        </camera>
        <plugin name='camera_dump' filename='libcamera_nao.so'/>
      </sensor>     
      <visual name="visual">
        <geometry>
          <mesh>
            <uri>model://pioneer2dxJde/meshes/sonyvid30/sonyvid30_top.dae</uri>
            <scale>1.5 1.5 1.5</scale>
          </mesh>
        </geometry>
      </visual>  
      <collision name="collision">
        <geometry>
          <box>
            <size>0.01 0.01 0.01</size>
          </box>
        </geometry>
        <surface>
          <friction>
            <ode>
              <mu>100000.0</mu>
              <mu2>100000.0</mu2>
              <slip1>0.0</slip1>
              <slip2>0.0</slip2>
            </ode>
          </friction>
        </surface>
      </collision>
    </link>
    <joint type="revolute" name="camera_bottom">
      <pose>0 0 0.023 0 0 0</pose>
      <child>HeadPitchLink</child>
      <parent>camera_head_bottom</parent>
      <axis>
        <limit>
          <lower>0</lower>
          <upper>0</upper>
        </limit>
        <xyz>0 0 0</xyz>
      </axis>
    </joint>

	<plugin filename="libposeneck.so" name="poseneck">
            <joint_poseneck_pan>HeadYaw</joint_poseneck_pan>
            <joint_poseneck_tilt>HeadPitch</joint_poseneck_tilt>
            <torque>5</torque>
        </plugin>

	<!--<plugin filename="libposeneckspeed.so" name="poseneckspeed">
            <joint_poseneckspeed_pan>HeadYaw</joint_poseneckspeed_pan>
            <joint_poseneckspeed_tilt>HeadPitch</joint_poseneckspeed_tilt>
            <torque>5</torque>
        </plugin>-->
	<plugin filename="libposerightshoulder.so" name="poserightshoulder">
            <joint_poserightshoulder_pitch>RShoulderPitch</joint_poserightshoulder_pitch>
            <joint_poserightshoulder_roll>RShoulderRoll</joint_poserightshoulder_roll>
            <torque>5</torque>
        </plugin>
	<plugin filename="libposeleftshoulder.so" name="poseleftshoulder">
            <joint_poseleftshoulder_pitch>LShoulderPitch</joint_poseleftshoulder_pitch>
            <joint_poseleftshoulder_roll>LShoulderRoll</joint_poseleftshoulder_roll>
            <torque>5</torque>
        </plugin>
	<plugin filename="libposerightelbow.so" name="poseencodersrightelbow">
            <joint_poserightelbow_yaw>RElbowYaw</joint_poserightelbow_yaw>
            <joint_poserightelbow_roll>RElbowRoll</joint_poserightelbow_roll>
            <torque>5</torque>
        </plugin> 
	<plugin filename="libposeleftelbow.so" name="poseleftelbow">
            <joint_poseleftelbow_yaw>LElbowYaw</joint_poseleftelbow_yaw>
            <joint_poseleftelbow_roll>LElbowRoll</joint_poseleftelbow_roll>
            <torque>5</torque>
        </plugin>
	<plugin filename="libposerighthip.so" name="poserighthip">
            <joint_poserighthip_yaw>RHipYawPitch</joint_poserighthip_yaw>
            <joint_poserighthip_roll>RHipRoll</joint_poserighthip_roll>
            <joint_poserighthip_pitch>RHipPitch</joint_poserighthip_pitch>
            <torque>5</torque>
        </plugin> 
        <plugin filename="libposelefthip.so" name="poselefthip">
            <joint_poselefthip_yaw>LHipYawPitch</joint_poselefthip_yaw>
            <joint_poselefthip_roll>LHipRoll</joint_poselefthip_roll>
            <joint_poselefthip_pitch>LHipPitch</joint_poselefthip_pitch>
            <torque>5</torque>
        </plugin> 
	<plugin filename="libposerightankle.so" name="poserightankle">
            <joint_poserightankle_pitch>RAnklePitch</joint_poserightankle_pitch>
            <joint_poserightankle_roll>RAnkleRoll</joint_poserightankle_roll>
            <torque>5</torque>
        </plugin>
	<plugin filename="libposeleftankle.so" name="poseleftankle">
            <joint_poseleftankle_pitch>LAnklePitch</joint_poseleftankle_pitch>
            <joint_poseleftankle_roll>LAnkleRoll</joint_poseleftankle_roll>
            <torque>5</torque>
        </plugin>
	<plugin filename="libposerightknee.so" name="poserightknee">
            <joint_poserightknee_pitch>RKneePitch</joint_poserightknee_pitch>
            <torque>5</torque>
        </plugin>
        
        <plugin filename="libposeleftknee.so" name="poseleftknee">
            <joint_poseleftknee_pitch>LKneePitch</joint_poseleftknee_pitch>
            <torque>5</torque>
        </plugin>

    <!--<plugin filename="libgazebo_ros_control.so" name="gazebo_ros_control">
      <robotNamespace>/nao_dcm</robotNamespace>
      <robotSimType>gazebo_ros_control/DefaultRobotHWSim</robotSimType>
    </plugin>
    <plugin name="gazebo_ros_imu_controller" filename="libgazebo_ros_imu.so">
      <robotNamespace>/nao_dcm</robotNamespace>
      <topicName>imu_data</topicName>
      <bodyName>imu</bodyName>
      <gaussianNoise>2.89e-08</gaussianNoise>
      <xyzOffsets>0 0 0</xyzOffsets>
      <rpyOffsets>0 0 0</rpyOffsets>
    </plugin> -->

  </model>
</sdf>
